{
 "cells": [
  {
   "cell_type": "code",
   "execution_count": 1,
   "metadata": {},
   "outputs": [
    {
     "ename": "ImportError",
     "evalue": "Traceback (most recent call last):\n  File \"/opt/homebrew/lib/python3.11/site-packages/tensorflow/python/pywrap_tensorflow.py\", line 58, in <module>\n    from tensorflow.python.pywrap_tensorflow_internal import *\n  File \"/opt/homebrew/lib/python3.11/site-packages/tensorflow/python/pywrap_tensorflow_internal.py\", line 28, in <module>\n    _pywrap_tensorflow_internal = swig_import_helper()\n                                  ^^^^^^^^^^^^^^^^^^^^\n  File \"/opt/homebrew/lib/python3.11/site-packages/tensorflow/python/pywrap_tensorflow_internal.py\", line 24, in swig_import_helper\n    _mod = imp.load_module('_pywrap_tensorflow_internal', fp, pathname, description)\n           ^^^^^^^^^^^^^^^^^^^^^^^^^^^^^^^^^^^^^^^^^^^^^^^^^^^^^^^^^^^^^^^^^^^^^^^^^\n  File \"/opt/homebrew/Cellar/python@3.11/3.11.2_1/Frameworks/Python.framework/Versions/3.11/lib/python3.11/imp.py\", line 243, in load_module\n    return load_dynamic(name, filename, file)\n           ^^^^^^^^^^^^^^^^^^^^^^^^^^^^^^^^^^\n  File \"/opt/homebrew/Cellar/python@3.11/3.11.2_1/Frameworks/Python.framework/Versions/3.11/lib/python3.11/imp.py\", line 343, in load_dynamic\n    return _load(spec)\n           ^^^^^^^^^^^\nImportError: dlopen(/opt/homebrew/lib/python3.11/site-packages/tensorflow/python/_pywrap_tensorflow_internal.so, 0x0006): tried: '/opt/homebrew/lib/python3.11/site-packages/tensorflow/python/_pywrap_tensorflow_internal.so' (mach-o file, but is an incompatible architecture (have 'x86_64', need 'arm64')), '/System/Volumes/Preboot/Cryptexes/OS/opt/homebrew/lib/python3.11/site-packages/tensorflow/python/_pywrap_tensorflow_internal.so' (no such file), '/opt/homebrew/lib/python3.11/site-packages/tensorflow/python/_pywrap_tensorflow_internal.so' (mach-o file, but is an incompatible architecture (have 'x86_64', need 'arm64'))\n\n\nFailed to load the native TensorFlow runtime.\n\nSee https://www.tensorflow.org/install/errors\n\nfor some common reasons and solutions.  Include the entire stack trace\nabove this error message when asking for help.",
     "output_type": "error",
     "traceback": [
      "\u001b[0;31m---------------------------------------------------------------------------\u001b[0m",
      "\u001b[0;31mImportError\u001b[0m                               Traceback (most recent call last)",
      "File \u001b[0;32m/opt/homebrew/lib/python3.11/site-packages/tensorflow/python/pywrap_tensorflow.py:58\u001b[0m\n\u001b[1;32m     56\u001b[0m   sys\u001b[39m.\u001b[39msetdlopenflags(_default_dlopen_flags \u001b[39m|\u001b[39m ctypes\u001b[39m.\u001b[39mRTLD_LOCAL)\n\u001b[0;32m---> 58\u001b[0m \u001b[39mfrom\u001b[39;00m \u001b[39mtensorflow\u001b[39;00m\u001b[39m.\u001b[39;00m\u001b[39mpython\u001b[39;00m\u001b[39m.\u001b[39;00m\u001b[39mpywrap_tensorflow_internal\u001b[39;00m \u001b[39mimport\u001b[39;00m \u001b[39m*\u001b[39m\n\u001b[1;32m     59\u001b[0m \u001b[39mfrom\u001b[39;00m \u001b[39mtensorflow\u001b[39;00m\u001b[39m.\u001b[39;00m\u001b[39mpython\u001b[39;00m\u001b[39m.\u001b[39;00m\u001b[39mpywrap_tensorflow_internal\u001b[39;00m \u001b[39mimport\u001b[39;00m __version__\n",
      "File \u001b[0;32m/opt/homebrew/lib/python3.11/site-packages/tensorflow/python/pywrap_tensorflow_internal.py:28\u001b[0m\n\u001b[1;32m     27\u001b[0m         \u001b[39mreturn\u001b[39;00m _mod\n\u001b[0;32m---> 28\u001b[0m _pywrap_tensorflow_internal \u001b[39m=\u001b[39m swig_import_helper()\n\u001b[1;32m     29\u001b[0m \u001b[39mdel\u001b[39;00m swig_import_helper\n",
      "File \u001b[0;32m/opt/homebrew/lib/python3.11/site-packages/tensorflow/python/pywrap_tensorflow_internal.py:24\u001b[0m, in \u001b[0;36mswig_import_helper\u001b[0;34m()\u001b[0m\n\u001b[1;32m     23\u001b[0m \u001b[39mtry\u001b[39;00m:\n\u001b[0;32m---> 24\u001b[0m     _mod \u001b[39m=\u001b[39m imp\u001b[39m.\u001b[39;49mload_module(\u001b[39m'\u001b[39;49m\u001b[39m_pywrap_tensorflow_internal\u001b[39;49m\u001b[39m'\u001b[39;49m, fp, pathname, description)\n\u001b[1;32m     25\u001b[0m \u001b[39mfinally\u001b[39;00m:\n",
      "File \u001b[0;32m/opt/homebrew/Cellar/python@3.11/3.11.2_1/Frameworks/Python.framework/Versions/3.11/lib/python3.11/imp.py:243\u001b[0m, in \u001b[0;36mload_module\u001b[0;34m(name, file, filename, details)\u001b[0m\n\u001b[1;32m    242\u001b[0m     \u001b[39melse\u001b[39;00m:\n\u001b[0;32m--> 243\u001b[0m         \u001b[39mreturn\u001b[39;00m load_dynamic(name, filename, file)\n\u001b[1;32m    244\u001b[0m \u001b[39melif\u001b[39;00m type_ \u001b[39m==\u001b[39m PKG_DIRECTORY:\n",
      "File \u001b[0;32m/opt/homebrew/Cellar/python@3.11/3.11.2_1/Frameworks/Python.framework/Versions/3.11/lib/python3.11/imp.py:343\u001b[0m, in \u001b[0;36mload_dynamic\u001b[0;34m(name, path, file)\u001b[0m\n\u001b[1;32m    341\u001b[0m spec \u001b[39m=\u001b[39m importlib\u001b[39m.\u001b[39mmachinery\u001b[39m.\u001b[39mModuleSpec(\n\u001b[1;32m    342\u001b[0m     name\u001b[39m=\u001b[39mname, loader\u001b[39m=\u001b[39mloader, origin\u001b[39m=\u001b[39mpath)\n\u001b[0;32m--> 343\u001b[0m \u001b[39mreturn\u001b[39;00m _load(spec)\n",
      "\u001b[0;31mImportError\u001b[0m: dlopen(/opt/homebrew/lib/python3.11/site-packages/tensorflow/python/_pywrap_tensorflow_internal.so, 0x0006): tried: '/opt/homebrew/lib/python3.11/site-packages/tensorflow/python/_pywrap_tensorflow_internal.so' (mach-o file, but is an incompatible architecture (have 'x86_64', need 'arm64')), '/System/Volumes/Preboot/Cryptexes/OS/opt/homebrew/lib/python3.11/site-packages/tensorflow/python/_pywrap_tensorflow_internal.so' (no such file), '/opt/homebrew/lib/python3.11/site-packages/tensorflow/python/_pywrap_tensorflow_internal.so' (mach-o file, but is an incompatible architecture (have 'x86_64', need 'arm64'))",
      "\nDuring handling of the above exception, another exception occurred:\n",
      "\u001b[0;31mImportError\u001b[0m                               Traceback (most recent call last)",
      "Cell \u001b[0;32mIn[1], line 1\u001b[0m\n\u001b[0;32m----> 1\u001b[0m \u001b[39mimport\u001b[39;00m \u001b[39mtensorflow\u001b[39;00m \u001b[39mas\u001b[39;00m \u001b[39mtf\u001b[39;00m\n",
      "File \u001b[0;32m/opt/homebrew/lib/python3.11/site-packages/tensorflow/__init__.py:24\u001b[0m\n\u001b[1;32m     21\u001b[0m \u001b[39mimport\u001b[39;00m \u001b[39mos\u001b[39;00m \u001b[39mas\u001b[39;00m \u001b[39m_os\u001b[39;00m\n\u001b[1;32m     23\u001b[0m \u001b[39m# pylint: disable=g-bad-import-order\u001b[39;00m\n\u001b[0;32m---> 24\u001b[0m \u001b[39mfrom\u001b[39;00m \u001b[39mtensorflow\u001b[39;00m\u001b[39m.\u001b[39;00m\u001b[39mpython\u001b[39;00m \u001b[39mimport\u001b[39;00m pywrap_tensorflow  \u001b[39m# pylint: disable=unused-import\u001b[39;00m\n\u001b[1;32m     26\u001b[0m \u001b[39mtry\u001b[39;00m:\n\u001b[1;32m     27\u001b[0m   \u001b[39m# Add `estimator` attribute to allow access to estimator APIs via\u001b[39;00m\n\u001b[1;32m     28\u001b[0m   \u001b[39m# \"tf.estimator...\"\u001b[39;00m\n\u001b[1;32m     29\u001b[0m   \u001b[39mfrom\u001b[39;00m \u001b[39mtensorflow\u001b[39;00m\u001b[39m.\u001b[39;00m\u001b[39mpython\u001b[39;00m\u001b[39m.\u001b[39;00m\u001b[39mestimator\u001b[39;00m\u001b[39m.\u001b[39;00m\u001b[39mapi\u001b[39;00m \u001b[39mimport\u001b[39;00m estimator  \u001b[39m# pylint: disable=g-import-not-at-top\u001b[39;00m\n",
      "File \u001b[0;32m/opt/homebrew/lib/python3.11/site-packages/tensorflow/python/__init__.py:49\u001b[0m\n\u001b[1;32m     32\u001b[0m \u001b[39m# TODO(drpng): write up instructions for editing this file in a doc and point to\u001b[39;00m\n\u001b[1;32m     33\u001b[0m \u001b[39m# the doc instead.\u001b[39;00m\n\u001b[1;32m     34\u001b[0m \u001b[39m# If you want to edit this file to expose modules in public tensorflow API, you\u001b[39;00m\n\u001b[0;32m   (...)\u001b[0m\n\u001b[1;32m     44\u001b[0m \u001b[39m# go/tf-wildcard-import\u001b[39;00m\n\u001b[1;32m     45\u001b[0m \u001b[39m# pylint: disable=wildcard-import,g-bad-import-order,g-import-not-at-top\u001b[39;00m\n\u001b[1;32m     47\u001b[0m \u001b[39mimport\u001b[39;00m \u001b[39mnumpy\u001b[39;00m \u001b[39mas\u001b[39;00m \u001b[39mnp\u001b[39;00m\n\u001b[0;32m---> 49\u001b[0m \u001b[39mfrom\u001b[39;00m \u001b[39mtensorflow\u001b[39;00m\u001b[39m.\u001b[39;00m\u001b[39mpython\u001b[39;00m \u001b[39mimport\u001b[39;00m pywrap_tensorflow\n\u001b[1;32m     51\u001b[0m \u001b[39mfrom\u001b[39;00m \u001b[39mtensorflow\u001b[39;00m\u001b[39m.\u001b[39;00m\u001b[39mpython\u001b[39;00m\u001b[39m.\u001b[39;00m\u001b[39mtools\u001b[39;00m \u001b[39mimport\u001b[39;00m component_api_helper\n\u001b[1;32m     52\u001b[0m component_api_helper\u001b[39m.\u001b[39mpackage_hook(\n\u001b[1;32m     53\u001b[0m     parent_package_str\u001b[39m=\u001b[39m\u001b[39m'\u001b[39m\u001b[39mtensorflow.python\u001b[39m\u001b[39m'\u001b[39m,\n\u001b[1;32m     54\u001b[0m     child_package_str\u001b[39m=\u001b[39m(\n\u001b[1;32m     55\u001b[0m         \u001b[39m'\u001b[39m\u001b[39mtensorflow_estimator.python.estimator\u001b[39m\u001b[39m'\u001b[39m))\n",
      "File \u001b[0;32m/opt/homebrew/lib/python3.11/site-packages/tensorflow/python/pywrap_tensorflow.py:74\u001b[0m\n\u001b[1;32m     69\u001b[0m \u001b[39mexcept\u001b[39;00m \u001b[39mImportError\u001b[39;00m:\n\u001b[1;32m     70\u001b[0m   msg \u001b[39m=\u001b[39m \u001b[39m\"\"\"\u001b[39m\u001b[39m%s\u001b[39;00m\u001b[39m\\n\u001b[39;00m\u001b[39m\\n\u001b[39;00m\u001b[39mFailed to load the native TensorFlow runtime.\u001b[39m\u001b[39m\\n\u001b[39;00m\n\u001b[1;32m     71\u001b[0m \u001b[39mSee https://www.tensorflow.org/install/errors\u001b[39m\u001b[39m\\n\u001b[39;00m\n\u001b[1;32m     72\u001b[0m \u001b[39mfor some common reasons and solutions.  Include the entire stack trace\u001b[39m\n\u001b[1;32m     73\u001b[0m \u001b[39mabove this error message when asking for help.\u001b[39m\u001b[39m\"\"\"\u001b[39m \u001b[39m%\u001b[39m traceback\u001b[39m.\u001b[39mformat_exc()\n\u001b[0;32m---> 74\u001b[0m   \u001b[39mraise\u001b[39;00m \u001b[39mImportError\u001b[39;00m(msg)\n\u001b[1;32m     76\u001b[0m \u001b[39m# pylint: enable=wildcard-import,g-import-not-at-top,unused-import,line-too-long\u001b[39;00m\n",
      "\u001b[0;31mImportError\u001b[0m: Traceback (most recent call last):\n  File \"/opt/homebrew/lib/python3.11/site-packages/tensorflow/python/pywrap_tensorflow.py\", line 58, in <module>\n    from tensorflow.python.pywrap_tensorflow_internal import *\n  File \"/opt/homebrew/lib/python3.11/site-packages/tensorflow/python/pywrap_tensorflow_internal.py\", line 28, in <module>\n    _pywrap_tensorflow_internal = swig_import_helper()\n                                  ^^^^^^^^^^^^^^^^^^^^\n  File \"/opt/homebrew/lib/python3.11/site-packages/tensorflow/python/pywrap_tensorflow_internal.py\", line 24, in swig_import_helper\n    _mod = imp.load_module('_pywrap_tensorflow_internal', fp, pathname, description)\n           ^^^^^^^^^^^^^^^^^^^^^^^^^^^^^^^^^^^^^^^^^^^^^^^^^^^^^^^^^^^^^^^^^^^^^^^^^\n  File \"/opt/homebrew/Cellar/python@3.11/3.11.2_1/Frameworks/Python.framework/Versions/3.11/lib/python3.11/imp.py\", line 243, in load_module\n    return load_dynamic(name, filename, file)\n           ^^^^^^^^^^^^^^^^^^^^^^^^^^^^^^^^^^\n  File \"/opt/homebrew/Cellar/python@3.11/3.11.2_1/Frameworks/Python.framework/Versions/3.11/lib/python3.11/imp.py\", line 343, in load_dynamic\n    return _load(spec)\n           ^^^^^^^^^^^\nImportError: dlopen(/opt/homebrew/lib/python3.11/site-packages/tensorflow/python/_pywrap_tensorflow_internal.so, 0x0006): tried: '/opt/homebrew/lib/python3.11/site-packages/tensorflow/python/_pywrap_tensorflow_internal.so' (mach-o file, but is an incompatible architecture (have 'x86_64', need 'arm64')), '/System/Volumes/Preboot/Cryptexes/OS/opt/homebrew/lib/python3.11/site-packages/tensorflow/python/_pywrap_tensorflow_internal.so' (no such file), '/opt/homebrew/lib/python3.11/site-packages/tensorflow/python/_pywrap_tensorflow_internal.so' (mach-o file, but is an incompatible architecture (have 'x86_64', need 'arm64'))\n\n\nFailed to load the native TensorFlow runtime.\n\nSee https://www.tensorflow.org/install/errors\n\nfor some common reasons and solutions.  Include the entire stack trace\nabove this error message when asking for help."
     ]
    }
   ],
   "source": [
    "import tensorflow as tf"
   ]
  },
  {
   "cell_type": "code",
   "execution_count": 1,
   "metadata": {},
   "outputs": [
    {
     "ename": "ImportError",
     "evalue": "Traceback (most recent call last):\n  File \"/opt/homebrew/lib/python3.11/site-packages/tensorflow/python/pywrap_tensorflow.py\", line 58, in <module>\n    from tensorflow.python.pywrap_tensorflow_internal import *\n  File \"/opt/homebrew/lib/python3.11/site-packages/tensorflow/python/pywrap_tensorflow_internal.py\", line 28, in <module>\n    _pywrap_tensorflow_internal = swig_import_helper()\n                                  ^^^^^^^^^^^^^^^^^^^^\n  File \"/opt/homebrew/lib/python3.11/site-packages/tensorflow/python/pywrap_tensorflow_internal.py\", line 24, in swig_import_helper\n    _mod = imp.load_module('_pywrap_tensorflow_internal', fp, pathname, description)\n           ^^^^^^^^^^^^^^^^^^^^^^^^^^^^^^^^^^^^^^^^^^^^^^^^^^^^^^^^^^^^^^^^^^^^^^^^^\n  File \"/opt/homebrew/Cellar/python@3.11/3.11.2_1/Frameworks/Python.framework/Versions/3.11/lib/python3.11/imp.py\", line 243, in load_module\n    return load_dynamic(name, filename, file)\n           ^^^^^^^^^^^^^^^^^^^^^^^^^^^^^^^^^^\n  File \"/opt/homebrew/Cellar/python@3.11/3.11.2_1/Frameworks/Python.framework/Versions/3.11/lib/python3.11/imp.py\", line 343, in load_dynamic\n    return _load(spec)\n           ^^^^^^^^^^^\nImportError: dlopen(/opt/homebrew/lib/python3.11/site-packages/tensorflow/python/_pywrap_tensorflow_internal.so, 0x0006): tried: '/opt/homebrew/lib/python3.11/site-packages/tensorflow/python/_pywrap_tensorflow_internal.so' (mach-o file, but is an incompatible architecture (have 'x86_64', need 'arm64')), '/System/Volumes/Preboot/Cryptexes/OS/opt/homebrew/lib/python3.11/site-packages/tensorflow/python/_pywrap_tensorflow_internal.so' (no such file), '/opt/homebrew/lib/python3.11/site-packages/tensorflow/python/_pywrap_tensorflow_internal.so' (mach-o file, but is an incompatible architecture (have 'x86_64', need 'arm64'))\n\n\nFailed to load the native TensorFlow runtime.\n\nSee https://www.tensorflow.org/install/errors\n\nfor some common reasons and solutions.  Include the entire stack trace\nabove this error message when asking for help.",
     "output_type": "error",
     "traceback": [
      "\u001b[0;31m---------------------------------------------------------------------------\u001b[0m",
      "\u001b[0;31mImportError\u001b[0m                               Traceback (most recent call last)",
      "File \u001b[0;32m/opt/homebrew/lib/python3.11/site-packages/tensorflow/python/pywrap_tensorflow.py:58\u001b[0m\n\u001b[1;32m     56\u001b[0m   sys\u001b[39m.\u001b[39msetdlopenflags(_default_dlopen_flags \u001b[39m|\u001b[39m ctypes\u001b[39m.\u001b[39mRTLD_LOCAL)\n\u001b[0;32m---> 58\u001b[0m \u001b[39mfrom\u001b[39;00m \u001b[39mtensorflow\u001b[39;00m\u001b[39m.\u001b[39;00m\u001b[39mpython\u001b[39;00m\u001b[39m.\u001b[39;00m\u001b[39mpywrap_tensorflow_internal\u001b[39;00m \u001b[39mimport\u001b[39;00m \u001b[39m*\u001b[39m\n\u001b[1;32m     59\u001b[0m \u001b[39mfrom\u001b[39;00m \u001b[39mtensorflow\u001b[39;00m\u001b[39m.\u001b[39;00m\u001b[39mpython\u001b[39;00m\u001b[39m.\u001b[39;00m\u001b[39mpywrap_tensorflow_internal\u001b[39;00m \u001b[39mimport\u001b[39;00m __version__\n",
      "File \u001b[0;32m/opt/homebrew/lib/python3.11/site-packages/tensorflow/python/pywrap_tensorflow_internal.py:28\u001b[0m\n\u001b[1;32m     27\u001b[0m         \u001b[39mreturn\u001b[39;00m _mod\n\u001b[0;32m---> 28\u001b[0m _pywrap_tensorflow_internal \u001b[39m=\u001b[39m swig_import_helper()\n\u001b[1;32m     29\u001b[0m \u001b[39mdel\u001b[39;00m swig_import_helper\n",
      "File \u001b[0;32m/opt/homebrew/lib/python3.11/site-packages/tensorflow/python/pywrap_tensorflow_internal.py:24\u001b[0m, in \u001b[0;36mswig_import_helper\u001b[0;34m()\u001b[0m\n\u001b[1;32m     23\u001b[0m \u001b[39mtry\u001b[39;00m:\n\u001b[0;32m---> 24\u001b[0m     _mod \u001b[39m=\u001b[39m imp\u001b[39m.\u001b[39;49mload_module(\u001b[39m'\u001b[39;49m\u001b[39m_pywrap_tensorflow_internal\u001b[39;49m\u001b[39m'\u001b[39;49m, fp, pathname, description)\n\u001b[1;32m     25\u001b[0m \u001b[39mfinally\u001b[39;00m:\n",
      "File \u001b[0;32m/opt/homebrew/Cellar/python@3.11/3.11.2_1/Frameworks/Python.framework/Versions/3.11/lib/python3.11/imp.py:243\u001b[0m, in \u001b[0;36mload_module\u001b[0;34m(name, file, filename, details)\u001b[0m\n\u001b[1;32m    242\u001b[0m     \u001b[39melse\u001b[39;00m:\n\u001b[0;32m--> 243\u001b[0m         \u001b[39mreturn\u001b[39;00m load_dynamic(name, filename, file)\n\u001b[1;32m    244\u001b[0m \u001b[39melif\u001b[39;00m type_ \u001b[39m==\u001b[39m PKG_DIRECTORY:\n",
      "File \u001b[0;32m/opt/homebrew/Cellar/python@3.11/3.11.2_1/Frameworks/Python.framework/Versions/3.11/lib/python3.11/imp.py:343\u001b[0m, in \u001b[0;36mload_dynamic\u001b[0;34m(name, path, file)\u001b[0m\n\u001b[1;32m    341\u001b[0m spec \u001b[39m=\u001b[39m importlib\u001b[39m.\u001b[39mmachinery\u001b[39m.\u001b[39mModuleSpec(\n\u001b[1;32m    342\u001b[0m     name\u001b[39m=\u001b[39mname, loader\u001b[39m=\u001b[39mloader, origin\u001b[39m=\u001b[39mpath)\n\u001b[0;32m--> 343\u001b[0m \u001b[39mreturn\u001b[39;00m _load(spec)\n",
      "\u001b[0;31mImportError\u001b[0m: dlopen(/opt/homebrew/lib/python3.11/site-packages/tensorflow/python/_pywrap_tensorflow_internal.so, 0x0006): tried: '/opt/homebrew/lib/python3.11/site-packages/tensorflow/python/_pywrap_tensorflow_internal.so' (mach-o file, but is an incompatible architecture (have 'x86_64', need 'arm64')), '/System/Volumes/Preboot/Cryptexes/OS/opt/homebrew/lib/python3.11/site-packages/tensorflow/python/_pywrap_tensorflow_internal.so' (no such file), '/opt/homebrew/lib/python3.11/site-packages/tensorflow/python/_pywrap_tensorflow_internal.so' (mach-o file, but is an incompatible architecture (have 'x86_64', need 'arm64'))",
      "\nDuring handling of the above exception, another exception occurred:\n",
      "\u001b[0;31mImportError\u001b[0m                               Traceback (most recent call last)",
      "Cell \u001b[0;32mIn[1], line 2\u001b[0m\n\u001b[1;32m      1\u001b[0m \u001b[39mimport\u001b[39;00m \u001b[39mnumpy\u001b[39;00m \u001b[39mas\u001b[39;00m \u001b[39mnp\u001b[39;00m\n\u001b[0;32m----> 2\u001b[0m \u001b[39mimport\u001b[39;00m \u001b[39mtensorflow\u001b[39;00m \u001b[39mas\u001b[39;00m \u001b[39mtf\u001b[39;00m\n\u001b[1;32m      3\u001b[0m \u001b[39mfrom\u001b[39;00m \u001b[39mtensorflow\u001b[39;00m \u001b[39mimport\u001b[39;00m keras\n\u001b[1;32m      4\u001b[0m \u001b[39mimport\u001b[39;00m \u001b[39mos\u001b[39;00m\n",
      "File \u001b[0;32m/opt/homebrew/lib/python3.11/site-packages/tensorflow/__init__.py:24\u001b[0m\n\u001b[1;32m     21\u001b[0m \u001b[39mimport\u001b[39;00m \u001b[39mos\u001b[39;00m \u001b[39mas\u001b[39;00m \u001b[39m_os\u001b[39;00m\n\u001b[1;32m     23\u001b[0m \u001b[39m# pylint: disable=g-bad-import-order\u001b[39;00m\n\u001b[0;32m---> 24\u001b[0m \u001b[39mfrom\u001b[39;00m \u001b[39mtensorflow\u001b[39;00m\u001b[39m.\u001b[39;00m\u001b[39mpython\u001b[39;00m \u001b[39mimport\u001b[39;00m pywrap_tensorflow  \u001b[39m# pylint: disable=unused-import\u001b[39;00m\n\u001b[1;32m     26\u001b[0m \u001b[39mtry\u001b[39;00m:\n\u001b[1;32m     27\u001b[0m   \u001b[39m# Add `estimator` attribute to allow access to estimator APIs via\u001b[39;00m\n\u001b[1;32m     28\u001b[0m   \u001b[39m# \"tf.estimator...\"\u001b[39;00m\n\u001b[1;32m     29\u001b[0m   \u001b[39mfrom\u001b[39;00m \u001b[39mtensorflow\u001b[39;00m\u001b[39m.\u001b[39;00m\u001b[39mpython\u001b[39;00m\u001b[39m.\u001b[39;00m\u001b[39mestimator\u001b[39;00m\u001b[39m.\u001b[39;00m\u001b[39mapi\u001b[39;00m \u001b[39mimport\u001b[39;00m estimator  \u001b[39m# pylint: disable=g-import-not-at-top\u001b[39;00m\n",
      "File \u001b[0;32m/opt/homebrew/lib/python3.11/site-packages/tensorflow/python/__init__.py:49\u001b[0m\n\u001b[1;32m     32\u001b[0m \u001b[39m# TODO(drpng): write up instructions for editing this file in a doc and point to\u001b[39;00m\n\u001b[1;32m     33\u001b[0m \u001b[39m# the doc instead.\u001b[39;00m\n\u001b[1;32m     34\u001b[0m \u001b[39m# If you want to edit this file to expose modules in public tensorflow API, you\u001b[39;00m\n\u001b[0;32m   (...)\u001b[0m\n\u001b[1;32m     44\u001b[0m \u001b[39m# go/tf-wildcard-import\u001b[39;00m\n\u001b[1;32m     45\u001b[0m \u001b[39m# pylint: disable=wildcard-import,g-bad-import-order,g-import-not-at-top\u001b[39;00m\n\u001b[1;32m     47\u001b[0m \u001b[39mimport\u001b[39;00m \u001b[39mnumpy\u001b[39;00m \u001b[39mas\u001b[39;00m \u001b[39mnp\u001b[39;00m\n\u001b[0;32m---> 49\u001b[0m \u001b[39mfrom\u001b[39;00m \u001b[39mtensorflow\u001b[39;00m\u001b[39m.\u001b[39;00m\u001b[39mpython\u001b[39;00m \u001b[39mimport\u001b[39;00m pywrap_tensorflow\n\u001b[1;32m     51\u001b[0m \u001b[39mfrom\u001b[39;00m \u001b[39mtensorflow\u001b[39;00m\u001b[39m.\u001b[39;00m\u001b[39mpython\u001b[39;00m\u001b[39m.\u001b[39;00m\u001b[39mtools\u001b[39;00m \u001b[39mimport\u001b[39;00m component_api_helper\n\u001b[1;32m     52\u001b[0m component_api_helper\u001b[39m.\u001b[39mpackage_hook(\n\u001b[1;32m     53\u001b[0m     parent_package_str\u001b[39m=\u001b[39m\u001b[39m'\u001b[39m\u001b[39mtensorflow.python\u001b[39m\u001b[39m'\u001b[39m,\n\u001b[1;32m     54\u001b[0m     child_package_str\u001b[39m=\u001b[39m(\n\u001b[1;32m     55\u001b[0m         \u001b[39m'\u001b[39m\u001b[39mtensorflow_estimator.python.estimator\u001b[39m\u001b[39m'\u001b[39m))\n",
      "File \u001b[0;32m/opt/homebrew/lib/python3.11/site-packages/tensorflow/python/pywrap_tensorflow.py:74\u001b[0m\n\u001b[1;32m     69\u001b[0m \u001b[39mexcept\u001b[39;00m \u001b[39mImportError\u001b[39;00m:\n\u001b[1;32m     70\u001b[0m   msg \u001b[39m=\u001b[39m \u001b[39m\"\"\"\u001b[39m\u001b[39m%s\u001b[39;00m\u001b[39m\\n\u001b[39;00m\u001b[39m\\n\u001b[39;00m\u001b[39mFailed to load the native TensorFlow runtime.\u001b[39m\u001b[39m\\n\u001b[39;00m\n\u001b[1;32m     71\u001b[0m \u001b[39mSee https://www.tensorflow.org/install/errors\u001b[39m\u001b[39m\\n\u001b[39;00m\n\u001b[1;32m     72\u001b[0m \u001b[39mfor some common reasons and solutions.  Include the entire stack trace\u001b[39m\n\u001b[1;32m     73\u001b[0m \u001b[39mabove this error message when asking for help.\u001b[39m\u001b[39m\"\"\"\u001b[39m \u001b[39m%\u001b[39m traceback\u001b[39m.\u001b[39mformat_exc()\n\u001b[0;32m---> 74\u001b[0m   \u001b[39mraise\u001b[39;00m \u001b[39mImportError\u001b[39;00m(msg)\n\u001b[1;32m     76\u001b[0m \u001b[39m# pylint: enable=wildcard-import,g-import-not-at-top,unused-import,line-too-long\u001b[39;00m\n",
      "\u001b[0;31mImportError\u001b[0m: Traceback (most recent call last):\n  File \"/opt/homebrew/lib/python3.11/site-packages/tensorflow/python/pywrap_tensorflow.py\", line 58, in <module>\n    from tensorflow.python.pywrap_tensorflow_internal import *\n  File \"/opt/homebrew/lib/python3.11/site-packages/tensorflow/python/pywrap_tensorflow_internal.py\", line 28, in <module>\n    _pywrap_tensorflow_internal = swig_import_helper()\n                                  ^^^^^^^^^^^^^^^^^^^^\n  File \"/opt/homebrew/lib/python3.11/site-packages/tensorflow/python/pywrap_tensorflow_internal.py\", line 24, in swig_import_helper\n    _mod = imp.load_module('_pywrap_tensorflow_internal', fp, pathname, description)\n           ^^^^^^^^^^^^^^^^^^^^^^^^^^^^^^^^^^^^^^^^^^^^^^^^^^^^^^^^^^^^^^^^^^^^^^^^^\n  File \"/opt/homebrew/Cellar/python@3.11/3.11.2_1/Frameworks/Python.framework/Versions/3.11/lib/python3.11/imp.py\", line 243, in load_module\n    return load_dynamic(name, filename, file)\n           ^^^^^^^^^^^^^^^^^^^^^^^^^^^^^^^^^^\n  File \"/opt/homebrew/Cellar/python@3.11/3.11.2_1/Frameworks/Python.framework/Versions/3.11/lib/python3.11/imp.py\", line 343, in load_dynamic\n    return _load(spec)\n           ^^^^^^^^^^^\nImportError: dlopen(/opt/homebrew/lib/python3.11/site-packages/tensorflow/python/_pywrap_tensorflow_internal.so, 0x0006): tried: '/opt/homebrew/lib/python3.11/site-packages/tensorflow/python/_pywrap_tensorflow_internal.so' (mach-o file, but is an incompatible architecture (have 'x86_64', need 'arm64')), '/System/Volumes/Preboot/Cryptexes/OS/opt/homebrew/lib/python3.11/site-packages/tensorflow/python/_pywrap_tensorflow_internal.so' (no such file), '/opt/homebrew/lib/python3.11/site-packages/tensorflow/python/_pywrap_tensorflow_internal.so' (mach-o file, but is an incompatible architecture (have 'x86_64', need 'arm64'))\n\n\nFailed to load the native TensorFlow runtime.\n\nSee https://www.tensorflow.org/install/errors\n\nfor some common reasons and solutions.  Include the entire stack trace\nabove this error message when asking for help."
     ]
    }
   ],
   "source": [
    "import numpy as np\n",
    "import tensorflow as tf\n",
    "from tensorflow import keras\n",
    "import os"
   ]
  },
  {
   "attachments": {},
   "cell_type": "markdown",
   "metadata": {},
   "source": [
    "Set the seed for reproducibility"
   ]
  },
  {
   "cell_type": "code",
   "execution_count": 6,
   "metadata": {},
   "outputs": [
    {
     "ename": "NameError",
     "evalue": "name 'tf' is not defined",
     "output_type": "error",
     "traceback": [
      "\u001b[0;31m---------------------------------------------------------------------------\u001b[0m",
      "\u001b[0;31mNameError\u001b[0m                                 Traceback (most recent call last)",
      "Cell \u001b[0;32mIn[6], line 2\u001b[0m\n\u001b[1;32m      1\u001b[0m np\u001b[39m.\u001b[39mrandom\u001b[39m.\u001b[39mseed(\u001b[39m123\u001b[39m)\n\u001b[0;32m----> 2\u001b[0m tf\u001b[39m.\u001b[39mrandom\u001b[39m.\u001b[39mset_seed(\u001b[39m123\u001b[39m)\n",
      "\u001b[0;31mNameError\u001b[0m: name 'tf' is not defined"
     ]
    }
   ],
   "source": [
    "np.random.seed(123)\n",
    "tf.random.set_seed(123)"
   ]
  },
  {
   "attachments": {},
   "cell_type": "markdown",
   "metadata": {},
   "source": [
    "Define the data paths"
   ]
  },
  {
   "cell_type": "code",
   "execution_count": null,
   "metadata": {},
   "outputs": [],
   "source": [
    "train_dir = \"/Users/rewanabdelqader/Collage/Semster8/Graduation_Project/DS/Sample/Train\"\n",
    "val_dir = \"/Users/rewanabdelqader/Collage/Semster8/Graduation_Project/DS/Sample/Val\"\n",
    "test_dir = \"/Users/rewanabdelqader/Collage/Semster8/Graduation_Project/DS/Sample/Test\""
   ]
  },
  {
   "attachments": {},
   "cell_type": "markdown",
   "metadata": {},
   "source": [
    "Define the image size and batch size"
   ]
  },
  {
   "cell_type": "code",
   "execution_count": null,
   "metadata": {},
   "outputs": [],
   "source": [
    "img_size = (256, 256)\n",
    "batch_size = 32"
   ]
  },
  {
   "attachments": {},
   "cell_type": "markdown",
   "metadata": {},
   "source": [
    "Define the data generators"
   ]
  },
  {
   "cell_type": "code",
   "execution_count": null,
   "metadata": {},
   "outputs": [],
   "source": [
    "train_datagen = tf.keras.preprocessing.image.ImageDataGenerator(\n",
    "    rescale=1./255,\n",
    "    rotation_range=20,\n",
    "    width_shift_range=0.2,\n",
    "    height_shift_range=0.2,\n",
    "    shear_range=0.2,\n",
    "    zoom_range=0.2,\n",
    "    horizontal_flip=True,\n",
    "    fill_mode='nearest'\n",
    ")\n",
    "val_datagen = tf.keras.preprocessing.image.ImageDataGenerator(\n",
    "    rescale=1./255\n",
    ")\n",
    "test_datagen = tf.keras.preprocessing.image.ImageDataGenerator(\n",
    "    rescale=1./255\n",
    ")\n",
    "\n",
    "train_generator = train_datagen.flow_from_directory(\n",
    "    train_dir,\n",
    "    target_size=img_size,\n",
    "    batch_size=batch_size,\n",
    "    class_mode='categorical'\n",
    ")\n",
    "val_generator = val_datagen.flow_from_directory(\n",
    "    val_dir,\n",
    "    target_size=img_size,\n",
    "    batch_size=batch_size,\n",
    "    class_mode='categorical'\n",
    ")\n",
    "test_generator = test_datagen.flow_from_directory(\n",
    "    test_dir,\n",
    "    target_size=img_size,\n",
    "    batch_size=batch_size,\n",
    "    class_mode='categorical'\n",
    ")"
   ]
  },
  {
   "attachments": {},
   "cell_type": "markdown",
   "metadata": {},
   "source": [
    "Build the model"
   ]
  },
  {
   "cell_type": "code",
   "execution_count": null,
   "metadata": {},
   "outputs": [],
   "source": [
    "model = tf.keras.models.Sequential([\n",
    "    tf.keras.layers.Conv2D(32, (3,3), activation='relu', input_shape=(256,256,3)),\n",
    "    tf.keras.layers.MaxPooling2D(2,2),\n",
    "    tf.keras.layers.Conv2D(64, (3,3), activation='relu'),\n",
    "    tf.keras.layers.MaxPooling2D(2,2),\n",
    "    tf.keras.layers.Conv2D(128, (3,3), activation='relu'),\n",
    "    tf.keras.layers.MaxPooling2D(2,2),\n",
    "    tf.keras.layers.Flatten(),\n",
    "    tf.keras.layers.Dense(128, activation='relu'),\n",
    "    tf.keras.layers.Dropout(0.5),\n",
    "    tf.keras.layers.Dense(3, activation='softmax')\n",
    "])"
   ]
  },
  {
   "attachments": {},
   "cell_type": "markdown",
   "metadata": {},
   "source": [
    "Compile the model"
   ]
  },
  {
   "cell_type": "code",
   "execution_count": null,
   "metadata": {},
   "outputs": [],
   "source": [
    "model.compile(loss='categorical_crossentropy', optimizer='adam', metrics=['accuracy'])"
   ]
  },
  {
   "attachments": {},
   "cell_type": "markdown",
   "metadata": {},
   "source": [
    "Train the model"
   ]
  },
  {
   "cell_type": "code",
   "execution_count": null,
   "metadata": {},
   "outputs": [],
   "source": [
    "history = model.fit(train_generator, epochs=20, validation_data=val_generator)"
   ]
  },
  {
   "attachments": {},
   "cell_type": "markdown",
   "metadata": {},
   "source": [
    "Evaluate the model on the test data"
   ]
  },
  {
   "cell_type": "code",
   "execution_count": null,
   "metadata": {},
   "outputs": [],
   "source": [
    "test_loss, test_acc = model.evaluate(test_generator)\n",
    "print(\"Test accuracy:\", test_acc)"
   ]
  }
 ],
 "metadata": {
  "kernelspec": {
   "display_name": "Python 3",
   "language": "python",
   "name": "python3"
  },
  "language_info": {
   "codemirror_mode": {
    "name": "ipython",
    "version": 3
   },
   "file_extension": ".py",
   "mimetype": "text/x-python",
   "name": "python",
   "nbconvert_exporter": "python",
   "pygments_lexer": "ipython3",
   "version": "3.11.2"
  },
  "orig_nbformat": 4
 },
 "nbformat": 4,
 "nbformat_minor": 2
}
